Workbook

Sheet Assumptions
A1: ALPHABET INC. (NASDAQ: GOOG / GOOGL) — INTEGRATED 3-STATEMENT MODEL
A2: Assumptions & Scenario Drivers
A3: $ in millions unless noted. Fiscal year = calendar year. Historicals (FY2021A-FY2025A) are hardcoded from Alphabet 10-K filings; all FY2026E-FY2030E cells are formulas.
A5: SCENARIO TOGGLE (1 = Base, 2 = Upside, 3 = Downside) | B5: 1
A6: Active scenario | B6: =CHOOSE($B$5,"Base","Upside","Downside") -> Base
C8: FY2021A | D8: FY2022A | E8: FY2023A | F8: FY2024A | G8: FY2025A | H8: FY2026E | I8: FY2027E | J8: FY2028E | K8: FY2029E | L8: FY2030E
A10: 1. REVENUE GROWTH (% y/y)
A11: Base case | H11: 0.21 | I11: 0.17 | J11: 0.14 | K11: 0.12 | L11: 0.11
A12: Upside case | H12: 0.235 | I12: 0.205 | J12: 0.18 | K12: 0.155 | L12: 0.14
A13: Downside case | H13: 0.185 | I13: 0.12 | J13: 0.09 | K13: 0.07 | L13: 0.06
A14: LIVE (selected scenario) | H14: =CHOOSE($B$5,H11,H12,H13) -> 0.21 | I14: =CHOOSE($B$5,I11,I12,I13) -> 0.17 | J14: =CHOOSE($B$5,J11,J12,J13) -> 0.14 | K14: =CHOOSE($B$5,K11,K12,K13) -> 0.12 | L14: =CHOOSE($B$5,L11,L12,L13) -> 0.11
A16: 2. COST OF REVENUES EX-DEPRECIATION (% of revenue)
A17: Base case | H17: 0.335 | I17: 0.332 | J17: 0.33 | K17: 0.328 | L17: 0.326
A18: Upside case | H18: 0.33 | I18: 0.322 | J18: 0.315 | K18: 0.31 | L18: 0.305
A19: Downside case | H19: 0.345 | I19: 0.355 | J19: 0.365 | K19: 0.372 | L19: 0.378
A20: LIVE (selected scenario) | H20: =CHOOSE($B$5,H17,H18,H19) -> 0.335 | I20: =CHOOSE($B$5,I17,I18,I19) -> 0.332 | J20: =CHOOSE($B$5,J17,J18,J19) -> 0.33 | K20: =CHOOSE($B$5,K17,K18,K19) -> 0.328 | L20: =CHOOSE($B$5,L17,L18,L19) -> 0.326
A22: 3. RESEARCH & DEVELOPMENT EX-DEPRECIATION (% of revenue)
A23: Base case | H23: 0.145 | I23: 0.144 | J23: 0.143 | K23: 0.142 | L23: 0.141
A24: Upside case | H24: 0.143 | I24: 0.14 | J24: 0.137 | K24: 0.135 | L24: 0.133
A25: Downside case | H25: 0.15 | I25: 0.156 | J25: 0.161 | K25: 0.165 | L25: 0.168
A26: LIVE (selected scenario) | H26: =CHOOSE($B$5,H23,H24,H25) -> 0.145 | I26: =CHOOSE($B$5,I23,I24,I25) -> 0.144 | J26: =CHOOSE($B$5,J23,J24,J25) -> 0.143 | K26: =CHOOSE($B$5,K23,K24,K25) -> 0.142 | L26: =CHOOSE($B$5,L23,L24,L25) -> 0.141
A28: 4. SALES & MARKETING (% of revenue)
A29: Base case | H29: 0.069 | I29: 0.068 | J29: 0.067 | K29: 0.066 | L29: 0.065
A30: Upside case | H30: 0.068 | I30: 0.066 | J30: 0.064 | K30: 0.063 | L30: 0.062
A31: Downside case | H31: 0.071 | I31: 0.073 | J31: 0.075 | K31: 0.076 | L31: 0.077
A32: LIVE (selected scenario) | H32: =CHOOSE($B$5,H29,H30,H31) -> 0.069 | I32: =CHOOSE($B$5,I29,I30,I31) -> 0.068 | J32: =CHOOSE($B$5,J29,J30,J31) -> 0.067 | K32: =CHOOSE($B$5,K29,K30,K31) -> 0.066 | L32: =CHOOSE($B$5,L29,L30,L31) -> 0.065
A34: 5. GENERAL & ADMINISTRATIVE (% of revenue)
A35: Base case | H35: 0.047 | I35: 0.045 | J35: 0.044 | K35: 0.043 | L35: 0.042
A36: Upside case | H36: 0.046 | I36: 0.043 | J36: 0.041 | K36: 0.04 | L36: 0.039
A37: Downside case | H37: 0.049 | I37: 0.05 | J37: 0.051 | K37: 0.052 | L37: 0.053
A38: LIVE (selected scenario) | H38: =CHOOSE($B$5,H35,H36,H37) -> 0.047 | I38: =CHOOSE($B$5,I35,I36,I37) -> 0.045 | J38: =CHOOSE($B$5,J35,J36,J37) -> 0.044 | K38: =CHOOSE($B$5,K35,K36,K37) -> 0.043 | L38: =CHOOSE($B$5,L35,L36,L37) -> 0.042
A40: 6. DEPRECIATION (% of beginning net PP&E)
A41: Base case | H41: 0.13 | I41: 0.15 | J41: 0.165 | K41: 0.175 | L41: 0.18
A42: Upside case | H42: 0.128 | I42: 0.143 | J42: 0.153 | K42: 0.16 | L42: 0.163
A43: Downside case | H43: 0.133 | I43: 0.158 | J43: 0.178 | K43: 0.192 | L43: 0.2
A44: LIVE (selected scenario) | H44: =CHOOSE($B$5,H41,H42,H43) -> 0.13 | I44: =CHOOSE($B$5,I41,I42,I43) -> 0.15 | J44: =CHOOSE($B$5,J41,J42,J43) -> 0.165 | K44: =CHOOSE($B$5,K41,K42,K43) -> 0.175 | L44: =CHOOSE($B$5,L41,L42,L43) -> 0.18
A46: 7. CAPITAL EXPENDITURE ($m)
A47: Base case | H47: 200000 | I47: 260000 | J47: 290000 | K47: 300000 | L47: 305000
A48: Upside case | H48: 200000 | I48: 255000 | J48: 275000 | K48: 290000 | L48: 295000
A49: Downside case | H49: 200000 | I49: 265000 | J49: 285000 | K49: 280000 | L49: 270000
...

Sheet IS
A1: ALPHABET INC. — CONSOLIDATED STATEMENTS OF INCOME
A2: Income Statement
A3: $ in millions unless noted. Fiscal year = calendar year. Historicals (FY2021A-FY2025A) are hardcoded from Alphabet 10-K filings; all FY2026E-FY2030E cells are formulas.
C5: FY2021A | D5: FY2022A | E5: FY2023A | F5: FY2024A | G5: FY2025A | H5: FY2026E | I5: FY2027E | J5: FY2028E | K5: FY2029E | L5: FY2030E
A6: Revenues | C6: 257637 | D6: 282836 | E6: 307394 | F6: 350018 | G6: 402836 | H6: =G6*(1+Assumptions!H$14) -> 487431.56 | I6: =H6*(1+Assumptions!I$14) -> 570294.93 | J6: =I6*(1+Assumptions!J$14) -> 650136.21 | K6: =J6*(1+Assumptions!K$14) -> 728152.56 | L6: =K6*(1+Assumptions!L$14) -> 808249.34
A7: Revenue growth % | D7: =D6/C6-1 -> 0.097808156 | E7: =E6/D6-1 -> 0.086827702 | F7: =F6/E6-1 -> 0.13866243 | G7: =G6/F6-1 -> 0.15090081 | H7: =H6/G6-1 -> 0.21 | I7: =I6/H6-1 -> 0.17 | J7: =J6/I6-1 -> 0.14 | K7: =K6/J6-1 -> 0.12 | L7: =L6/K6-1 -> 0.11
A8: Costs and expenses:
A9: Cost of revenues | C9: 110939 | D9: 126203 | E9: 133332 | F9: 146306 | G9: 162535 | H9: =H6*Assumptions!H$20+H31*Assumptions!H$59 -> 190538.54 | I9: =I6*Assumptions!I$20+I31*Assumptions!I$59 -> 242191.69 | J9: =J6*Assumptions!J$20+J31*Assumptions!J$59 -> 300428.23 | K9: =K6*Assumptions!K$20+K31*Assumptions!K$59 -> 358030.29 | L9: =L6*Assumptions!L$20+L31*Assumptions!L$59 -> 410535.82
A10: Research and development | C10: 31562 | D10: 39500 | E10: 45427 | F10: 49326 | G10: 61087 | H10: =H6*Assumptions!H$26+H31*(1-Assumptions!H$59) -> 75486.218 | I10: =I6*Assumptions!I$26+I31*(1-Assumptions!I$59) -> 91449.606 | J10: =J6*Assumptions!J$26+J31*(1-Assumptions!J$59) -> 108125.35 | K10: =K6*Assumptions!K$26+K31*(1-Assumptions!K$59) -> 124432.3 | L10: =L6*Assumptions!L$26+L31*(1-Assumptions!L$59) -> 139912.55
A11: Sales and marketing | C11: 22912 | D11: 26567 | E11: 27917 | F11: 27808 | G11: 28693 | H11: =H6*Assumptions!H$32 -> 33632.778 | I11: =I6*Assumptions!I$32 -> 38780.055 | J11: =J6*Assumptions!J$32 -> 43559.126 | K11: =K6*Assumptions!K$32 -> 48058.069 | L11: =L6*Assumptions!L$32 -> 52536.207
A12: General and administrative | C12: 13510 | D12: 15724 | E12: 16425 | F12: 14188 | G12: 21482 | H12: =H6*Assumptions!H$38 -> 22909.283 | I12: =I6*Assumptions!I$38 -> 25663.272 | J12: =J6*Assumptions!J$38 -> 28605.993 | K12: =K6*Assumptions!K$38 -> 31310.56 | L12: =L6*Assumptions!L$38 -> 33946.472
A13: Total costs and expenses | C13: =SUM(C9:C12) -> 178923 | D13: =SUM(D9:D12) -> 207994 | E13: =SUM(E9:E12) -> 223101 | F13: =SUM(F9:F12) -> 237628 | G13: =SUM(G9:G12) -> 273797 | H13: =SUM(H9:H12) -> 322566.82 | I13: =SUM(I9:I12) -> 398084.62 | J13: =SUM(J9:J12) -> 480718.7 | ... L13: =SUM(L9:L12) -> 636931.04
A14: Income from operations | C14: =C6-C13 -> 78714 | D14: =D6-D13 -> 74842 | E14: =E6-E13 -> 84293 | F14: =F6-F13 -> 112390 | G14: =G6-G13 -> 129039 | H14: =H6-H13 -> 164864.74 | I14: =I6-I13 -> 172210.31 | J14: =J6-J13 -> 169417.52 | ... L14: =L6-L13 -> 171318.3
A15: Operating margin % | C15: =C14/C6 -> 0.30552289 | D15: =D14/D6 -> 0.26461271 | E15: =E14/E6 -> 0.2742181 | F15: =F14/F6 -> 0.32109777 | G15: =G14/G6 -> 0.32032639 | H15: =H14/H6 -> 0.33823157 | I15: =I14/I6 -> 0.3019671 | J15: =J14/J6 -> 0.26058772 | ... L15: =L14/L6 -> 0.21196219
A17: Interest and investment income | H17: =Assumptions!H$61*(BS!G7+BS!G8) -> 5073.72 | I17: =Assumptions!I$61*(BS!H7+BS!H8) -> 5171.8553 | J17: =Assumptions!J$61*(BS!I7+BS!I8) -> 4259.8322 | K17: =Assumptions!K$61*(BS!J7+BS!J8) -> 2969.2131 | L17: =Assumptions!L$61*(BS!K7+BS!K8) -> 1723.4952
A18: Interest expense | H18: =-Assumptions!H$62*BS!G28 -> -2001.521 | I18: =-Assumptions!I$62*BS!H28 -> -4456.936 | J18: =-Assumptions!J$62*BS!I28 -> -6084.936 | K18: =-Assumptions!K$62*BS!J28 -> -7798.23 | L18: =-Assumptions!L$62*BS!K28 -> -9058.23
A19: Other non-operating income (expense), net | H19: =Assumptions!H$63 -> 0 | I19: =Assumptions!I$63 -> 0 | J19: =Assumptions!J$63 -> 0 | K19: =Assumptions!K$63 -> 0 | L19: =Assumptions!L$63 -> 0
A20: Other income (expense), net | C20: 12020 | D20: -3514 | E20: 1424 | F20: 7425 | G20: 29787 | H20: =H17+H18+H19 -> 3072.199 | I20: =I17+I18+I19 -> 714.91933 | J20: =J17+J18+J19 -> -1825.1038 | K20: =K17+K18+K19 -> -4829.0169 | L20: =L17+L18+L19 -> -7334.7348
A21: Income before income taxes | C21: =C14+C20 -> 90734 | D21: =D14+D20 -> 71328 | E21: =E14+E20 -> 85717 | F21: =F14+F20 -> 119815 | G21: =G14+G20 -> 158826 | H21: =H14+H20 -> 167936.94 | I21: =I14+I20 -> 172925.23 | J21: =J14+J20 -> 167592.41 | ... L21: =L14+L20 -> 163983.56
A22: Provision for income taxes | C22: 14701 | D22: 11356 | E22: 11922 | F22: 19697 | G22: 26656 | H22: =H21*Assumptions!H$56 -> 31908.018 | I22: =I21*Assumptions!I$56 -> 32855.793 | J22: =J21*Assumptions!J$56 -> 31842.558 | K22: =K21*Assumptions!K$56 -> 30683.542 | L22: =L21*Assumptions!L$56 -> 31156.877
A23: Effective tax rate % | C23: =C22/C21 -> 0.16202306 | D23: =D22/D21 -> 0.15920817 | E23: =E22/E21 -> 0.1390856 | F23: =F22/F21 -> 0.16439511 | G23: =G22/G21 -> 0.16783146 | H23: =H22/H21 -> 0.19 | I23: =I22/I21 -> 0.19 | J23: =J22/J21 -> 0.19 | ... L23: =L22/L21 -> 0.19
A24: Net income | C24: =C21-C22 -> 76033 | D24: =D21-D22 -> 59972 | E24: =E21-E22 -> 73795 | F24: =F21-F22 -> 100118 | G24: =G21-G22 -> 132170 | H24: =H21-H22 -> 136028.92 | I24: =I21-I22 -> 140069.43 | J24: =J21-J22 -> 135749.85 | ... L24: =L21-L22 -> 132826.69
A25: Preferred stock dividends | C25: 0 | D25: 0 | E25: 0 | F25: 0 | G25: 0 | H25: =Assumptions!H$94 -> 400 | I25: =Assumptions!I$94 -> 1188 | J25: =Assumptions!J$94 -> 1188 | K25: =Assumptions!K$94 -> 1188 | L25: =Assumptions!L$94 -> 1188
A26: Net income available to common stockholders | C26: =C24-C25 -> 76033 | D26: =D24-D25 -> 59972 | E26: =E24-E25 -> 73795 | F26: =F24-F25 -> 100118 | G26: =G24-G25 -> 132170 | H26: =H24-H25 -> 135628.92 | I26: =I24-I25 -> 138881.43 | J26: =J24-J25 -> 134561.85 | ... L26: =L24-L25 -> 131638.69
A28: Diluted weighted-average shares (m) | C28: 13553 | D28: 13159 | E28: 12722 | F28: 12447 | G28: 12230 | H28: =G28*(1+Assumptions!H$95) -> 12450.14 | I28: =H28*(1+Assumptions!I$95) -> 12562.191 | J28: =I28*(1+Assumptions!J$95) -> 12599.878 | K28: =J28*(1+Assumptions!K$95) -> 12574.678 | L28: =K28*(1+Assumptions!L$95) -> 12511.805
A29: Diluted earnings per share ($) | C29: =C26/C28 -> 5.6100494 | D29: =D26/D28 -> 4.5574892 | E29: =E26/E28 -> 5.8005817 | F29: =F26/F28 -> 8.0435446 | G29: =G26/G28 -> 10.807032 | H29: =H26/H28 -> 10.893767 | I29: =I26/I28 -> 11.05551 | J29: =J26/J28 -> 10.679616 | ... L29: =L26/L28 -> 10.521159
A31: Memo: Depreciation of property and equipment | C31: 10273 | D31: 13475 | E31: 11946 | F31: 15311 | G31: 21136 | H31: =Schedules!H8 -> 32057.61 | I31: =Schedules!I8 -> 62180.908 | J31: =Schedules!J8 -> 101039.15 | K31: =Schedules!K8 -> 140230.88 | L31: =Schedules!L8 -> 172995.92
A32: Memo: EBITDA | C32: =C14+C31 -> 88987 | D32: =D14+D31 -> 88317 | E32: =E14+E31 -> 96239 | F32: =F14+F31 -> 127701 | G32: =G14+G31 -> 150175 | H32: =H14+H31 -> 196922.35 | I32: =I14+I31 -> 234391.21 | J32: =J14+J31 -> 270456.67 | ... L32: =L14+L31 -> 344314.22
A33: Memo: Stock-based compensation | C33: 15376 | D33: 19362 | E33: 22460 | F33: 22785 | G33: 24953 | H33: =H6*Assumptions!H$60 -> 30220.757 | I33: =I6*Assumptions!I$60 -> 34217.696 | J33: =J6*Assumptions!J$60 -> 37707.9 | K33: =K6*Assumptions!K$60 -> 40776.543 | L33: =L6*Assumptions!L$60 -> 44453.714

Sheet BS
A1: ALPHABET INC. — CONSOLIDATED BALANCE SHEETS
A2: Balance Sheet
A3: $ in millions unless noted. Fiscal year = calendar year. Historicals (FY2021A-FY2025A) are hardcoded from Alphabet 10-K filings; all FY2026E-FY2030E cells are formulas.
C5: FY2021A | D5: FY2022A | E5: FY2023A | F5: FY2024A | G5: FY2025A | H5: FY2026E | I5: FY2027E | J5: FY2028E | K5: FY2029E | L5: FY2030E
A6: Assets
A7: Cash and cash equivalents | C7: 20945 | D7: 21879 | E7: 24048 | F7: 23466 | G7: 30708 | H7: =CF!H47 -> -13898.544 | I7: =CF!I47 -> -11671.327 | J7: =CF!J47 -> -30165.339 | K7: =CF!K47 -> -55757.281 | L7: =CF!L47 -> -82879.486
A8: Marketable securities | C8: 118704 | D8: 91883 | E8: 86868 | F8: 72191 | G8: 96135 | H8: =Assumptions!H$79 -> 150000 | I8: =Assumptions!I$79 -> 130000 | J8: =Assumptions!J$79 -> 115000 | K8: =Assumptions!K$79 -> 105000 | L8: =Assumptions!L$79 -> 105000
A9: Accounts receivable, net | C9: 39304 | D9: 40258 | E9: 47964 | F9: 52340 | G9: 62886 | H9: =IS!H6*Assumptions!H$66/365 -> 76119.449 | I9: =IS!I6*Assumptions!I$66/365 -> 89059.755 | J9: =IS!J6*Assumptions!J$66/365 -> 101528.12 | K9: =IS!K6*Assumptions!K$66/365 -> 113711.5 | L9: =IS!L6*Assumptions!L$66/365 -> 126219.76
A10: Inventory | C10: 1170 | D10: 0 | E10: 0 | F10: 0 | G10: 2439 | H10: =IS!H9*Assumptions!H$68 -> 9526.9271 | I10: =IS!I9*Assumptions!I$68 -> 13320.543 | J10: =IS!J9*Assumptions!J$68 -> 17424.837 | K10: =IS!K9*Assumptions!K$68 -> 21481.817 | L10: =IS!L9*Assumptions!L$68 -> 24632.149
A11: Other current assets | C11: 8020 | D11: 10775 | E11: 12650 | F11: 15714 | G11: 13870 | H11: =IS!H6*Assumptions!H$69 -> 19497.262 | I11: =IS!I6*Assumptions!I$69 -> 22811.797 | J11: =IS!J6*Assumptions!J$69 -> 26005.449 | K11: =IS!K6*Assumptions!K$69 -> 29126.102 | L11: =IS!L6*Assumptions!L$69 -> 32329.974
A12: Total current assets | C12: =SUM(C7:C11) -> 188143 | D12: =SUM(D7:D11) -> 164795 | E12: =SUM(E7:E11) -> 171530 | F12: =SUM(F7:F11) -> 163711 | G12: =SUM(G7:G11) -> 206038 | H12: =SUM(H7:H11) -> 241245.09 | I12: =SUM(I7:I11) -> 243520.77 | J12: =SUM(J7:J11) -> 229793.07 | ... L12: =SUM(L7:L11) -> 205302.4
A13: Non-marketable securities | C13: 29549 | D13: 30492 | E13: 31008 | F13: 37982 | G13: 68687 | H13: =G13+Assumptions!H$80+Assumptions!H$63 -> 90738 | I13: =H13+Assumptions!I$80+Assumptions!I$63 -> 95738 | J13: =I13+Assumptions!J$80+Assumptions!J$63 -> 100738 | K13: =J13+Assumptions!K$80+Assumptions!K$63 -> 105738 | L13: =K13+Assumptions!L$80+Assumptions!L$63 -> 110738
A14: Deferred income taxes, net | C14: 1284 | D14: 5261 | E14: 12169 | F14: 17180 | G14: 9113 | H14: =Assumptions!H$82 -> 1448 | I14: =Assumptions!I$82 -> 1448 | J14: =Assumptions!J$82 -> 1448 | K14: =Assumptions!K$82 -> 1448 | L14: =Assumptions!L$82 -> 1448
A15: Property and equipment, net | C15: 97599 | D15: 112668 | E15: 134345 | F15: 171036 | G15: 246597 | H15: =Schedules!H10 -> 414539.39 | I15: =Schedules!I10 -> 612358.48 | J15: =Schedules!J10 -> 801319.33 | K15: =Schedules!K10 -> 961088.45 | L15: =Schedules!L10 -> 1093092.5
A16: Operating lease assets | C16: 12959 | D16: 14381 | E16: 14091 | F16: 13588 | G16: 15221 | H16: =IS!H6*Assumptions!H$74 -> 18034.968 | I16: =IS!I6*Assumptions!I$74 -> 21100.912 | J16: =IS!J6*Assumptions!J$74 -> 24055.04 | K16: =IS!K6*Assumptions!K$74 -> 26941.645 | L16: =IS!L6*Assumptions!L$74 -> 29905.226
A17: Goodwill and intangible assets | C17: 22956 | D17: 28960 | E17: 29198 | F17: 31885 | G17: 34663 | H17: =G17+Assumptions!H$81 -> 68360 | I17: =H17+Assumptions!I$81 -> 70360 | J17: =I17+Assumptions!J$81 -> 72360 | K17: =J17+Assumptions!K$81 -> 74360 | L17: =K17+Assumptions!L$81 -> 76360
A18: Other non-current assets | C18: 6778 | D18: 8707 | E18: 10051 | F18: 14874 | G18: 14962 | H18: =IS!H6*Assumptions!H$76 -> 21934.42 | I18: =IS!I6*Assumptions!I$76 -> 25663.272 | J18: =IS!J6*Assumptions!J$76 -> 29256.13 | K18: =IS!K6*Assumptions!K$76 -> 32766.865 | L18: =IS!L6*Assumptions!L$76 -> 36371.22
A19: Total assets | C19: =C12+SUM(C13:C18) -> 359268 | D19: =D12+SUM(D13:D18) -> 365264 | E19: =E12+SUM(E13:E18) -> 402392 | F19: =F12+SUM(F13:F18) -> 450256 | G19: =G12+SUM(G13:G18) -> 595281 | H19: =H12+SUM(H13:H18) -> 856299.87 | I19: =I12+SUM(I13:I18) -> 1070189.4 | J19: =J12+SUM(J13:J18) -> 1258969.6 | ... L19: =L12+SUM(L13:L18) -> 1553217.4
A21: Liabilities and Stockholders' Equity
A22: Accounts payable | C22: 6037 | D22: 5128 | E22: 7493 | F22: 7987 | G22: 12200 | H22: =IS!H9*Assumptions!H$67/365 -> 15660.702 | I22: =IS!I9*Assumptions!I$67/365 -> 19906.166 | J22: =IS!J9*Assumptions!J$67/365 -> 24692.731 | K22: =IS!K9*Assumptions!K$67/365 -> 29427.147 | L22: =IS!L9*Assumptions!L$67/365 -> 33742.67
A23: Accrued compensation and benefits | C23: 13889 | D23: 14028 | E23: 15140 | F23: 15069 | G23: 17546 | H23: =IS!H6*Assumptions!H$70 -> 19497.262 | I23: =IS!I6*Assumptions!I$70 -> 22811.797 | J23: =IS!J6*Assumptions!J$70 -> 26005.449 | K23: =IS!K6*Assumptions!K$70 -> 29126.102 | L23: =IS!L6*Assumptions!L$70 -> 32329.974
A24: Accrued expenses and other current liabilities | C24: 32044 | D24: 37866 | E24: 46168 | F24: 51228 | G24: 55557 | H24: =IS!H6*Assumptions!H$71 -> 68240.418 | I24: =IS!I6*Assumptions!I$71 -> 79841.29 | J24: =IS!J6*Assumptions!J$71 -> 91019.07 | K24: =IS!K6*Assumptions!K$71 -> 101941.36 | L24: =IS!L6*Assumptions!L$71 -> 113154.91
A25: Accrued revenue share | C25: 8996 | D25: 8370 | E25: 8876 | F25: 9802 | G25: 10864 | H25: =IS!H6*Assumptions!H$72 -> 12673.221 | I25: =IS!I6*Assumptions!I$72 -> 14827.668 | J25: =IS!J6*Assumptions!J$72 -> 16903.542 | K25: =IS!K6*Assumptions!K$72 -> 18931.967 | L25: =IS!L6*Assumptions!L$72 -> 21014.483
A26: Deferred revenue | C26: 3288 | D26: 3908 | E26: 4137 | F26: 5036 | G26: 6578 | H26: =IS!H6*Assumptions!H$73 -> 8286.3365 | I26: =IS!I6*Assumptions!I$73 -> 9695.0137 | J26: =IS!J6*Assumptions!J$73 -> 11052.316 | K26: =IS!K6*Assumptions!K$73 -> 12378.594 | L26: =IS!L6*Assumptions!L$73 -> 13740.239
A27: Total current liabilities | C27: =SUM(C22:C26) -> 64254 | D27: =SUM(D22:D26) -> 69300 | E27: =SUM(E22:E26) -> 81814 | F27: =SUM(F22:F26) -> 89122 | G27: =SUM(G22:G26) -> 102745 | H27: =SUM(H22:H26) -> 124357.94 | I27: =SUM(I22:I26) -> 147081.93 | J27: =SUM(J22:J26) -> 169673.11 | ... L27: =SUM(L22:L26) -> 213982.27
A28: Long-term debt | C28: 14817 | D28: 14701 | E28: 13253 | F28: 10883 | G28: 46547 | H28: =Schedules!H20 -> 101294 | I28: =Schedules!I20 -> 138294 | J28: =Schedules!J20 -> 173294 | K28: =Schedules!K20 -> 201294 | L28: =Schedules!L20 -> 226294
A29: Income taxes payable, non-current | C29: 9176 | D29: 9258 | E29: 8474 | F29: 8782 | G29: 9531 | H29: =Assumptions!H$83 -> 11306 | I29: =Assumptions!I$83 -> 11500 | J29: =Assumptions!J$83 -> 11800 | K29: =Assumptions!K$83 -> 12000 | L29: =Assumptions!L$83 -> 12200
A30: Operating lease liabilities | C30: 11389 | D30: 12501 | E30: 12460 | F30: 11691 | G30: 12744 | H30: =IS!H6*Assumptions!H$75 -> 15110.378 | I30: =IS!I6*Assumptions!I$75 -> 17679.143 | J30: =IS!J6*Assumptions!J$75 -> 20154.223 | K30: =IS!K6*Assumptions!K$75 -> 22572.729 | L30: =IS!L6*Assumptions!L$75 -> 25055.73
A31: Other long-term liabilities | C31: 7997 | D31: 3360 | E31: 3012 | F31: 4694 | G31: 8449 | H31: =Assumptions!H$84 -> 8511 | I31: =Assumptions!I$84 -> 9000 | J31: =Assumptions!J$84 -> 9500 | K31: =Assumptions!K$84 -> 10000 | L31: =Assumptions!L$84 -> 10500
A32: Total liabilities | C32: =C27+SUM(C28:C31) -> 107633 | D32: =D27+SUM(D28:D31) -> 109120 | E32: =E27+SUM(E28:E31) -> 119013 | F32: =F27+SUM(F28:F31) -> 125172 | G32: =G27+SUM(G28:G31) -> 180016 | H32: =H27+SUM(H28:H31) -> 260579.32 | I32: =I27+SUM(I28:I31) -> 323555.08 | J32: =J27+SUM(J28:J31) -> 384421.33 | ... L32: =L27+SUM(L28:L31) -> 488032
A34: Preferred stock and additional paid-in capital | C34: 0 | D34: 0 | E34: 0 | F34: 0 | G34: 0 | H34: =G34+Schedules!H35 -> 18023 | I34: =H34+Schedules!I35 -> 18023 | J34: =I34+Schedules!J35 -> 18023 | K34: =J34+Schedules!K35 -> 18023 | L34: =K34+Schedules!L35 -> 18023
A35: Class A/B/C stock and additional paid-in capital | C35: 61774 | D35: 68184 | E35: 76534 | F35: 84800 | G35: 93126 | H35: =G35+Schedules!H32-Schedules!H33+Schedules!H34 -> 130885.76 | I35: =H35+Schedules!I32-Schedules!I33+Schedules!I34 -> 155103.45 | J35: =I35+Schedules!J32-Schedules!J33+Schedules!J34 -> 181811.35 | K35: =J35+Schedules!K32-Schedules!K33+Schedules!K34 -> 210587.9 | L35: =K35+Schedules!L32-Schedules!L33+Schedules!L34 -> 242041.61
A36: Accumulated other comprehensive income (loss) | C36: -1623 | D36: -7603 | E36: -4402 | F36: -4800 | G36: -1916 | H36: =G36 -> -1916 | I36: =H36 -> -1916 | J36: =I36 -> -1916 | K36: =J36 -> -1916 | L36: =K36 -> -1916
A37: Retained earnings | C37: 191484 | D37: 195563 | E37: 211247 | F37: 245084 | G37: 324055 | H37: =G37+IS!H24-Schedules!H29-Schedules!H30-Schedules!H31 -> 448727.8 | I37: =H37+IS!I24-Schedules!I29-Schedules!I30-Schedules!I31 -> 575423.9 | J37: =I37+IS!J24-Schedules!J29-Schedules!J30-Schedules!J31 -> 676629.89 | K37: =J37+IS!K24-Schedules!K29-Schedules!K30-Schedules!K31 -> 751538.3 | L37: =K37+IS!L24-Schedules!L29-Schedules!L30-Schedules!L31 -> 807036.76
A38: Total stockholders' equity | C38: =SUM(C34:C37) -> 251635 | D38: =SUM(D34:D37) -> 256144 | E38: =SUM(E34:E37) -> 283379 | F38: =SUM(F34:F37) -> 325084 | G38: =SUM(G34:G37) -> 415265 | H38: =SUM(H34:H37) -> 595720.55 | I38: =SUM(I34:I37) -> 746634.36 | J38: =SUM(J34:J37) -> 874548.24 | ... L38: =SUM(L34:L37) -> 1065185.4
A39: Total liabilities and stockholders' equity | C39: =C32+C38 -> 359268 | D39: =D32+D38 -> 365264 | E39: =E32+E38 -> 402392 | F39: =F32+F38 -> 450256 | G39: =G32+G38 -> 595281 | H39: =H32+H38 -> 856299.87 | I39: =I32+I38 -> 1070189.4 | J39: =J32+J38 -> 1258969.6 | ... L39: =L32+L38 -> 1553217.4
A41: CHECK: Total assets less total liabilities and equity (must = 0) | C41: =C19-C39 -> 0 | D41: =D19-D39 -> 0 | E41: =E19-E39 -> 0 | F41: =F19-F39 -> 0 | G41: =G19-G39 -> 0 | H41: =H19-H39 -> 0 | I41: =I19-I39 -> 0 | J41: =J19-J39 -> 0 | ... L41: =L19-L39 -> 0

Sheet CF
A1: ALPHABET INC. — CONSOLIDATED STATEMENTS OF CASH FLOWS
A2: Cash Flow Statement
A3: $ in millions unless noted. Fiscal year = calendar year. Historicals (FY2021A-FY2025A) are hardcoded from Alphabet 10-K filings; all FY2026E-FY2030E cells are formulas.
C5: FY2021A | D5: FY2022A | E5: FY2023A | F5: FY2024A | G5: FY2025A | H5: FY2026E | I5: FY2027E | J5: FY2028E | K5: FY2029E | L5: FY2030E
A6: Operating activities
A7: Net income | C7: =IS!C24 -> 76033 | D7: =IS!D24 -> 59972 | E7: =IS!E24 -> 73795 | F7: =IS!F24 -> 100118 | G7: =IS!G24 -> 132170 | H7: =IS!H24 -> 136028.92 | I7: =IS!I24 -> 140069.43 | J7: =IS!J24 -> 135749.85 | ... L7: =IS!L24 -> 132826.69
A8: Depreciation of property and equipment | C8: 10273 | D8: 13475 | E8: 11946 | F8: 15311 | G8: 21136 | H8: =Schedules!H8 -> 32057.61 | I8: =Schedules!I8 -> 62180.908 | J8: =Schedules!J8 -> 101039.15 | K8: =Schedules!K8 -> 140230.88 | L8: =Schedules!L8 -> 172995.92
A9: Stock-based compensation expense | C9: 15376 | D9: 19362 | E9: 22460 | F9: 22785 | G9: 24953 | H9: =IS!H33 -> 30220.757 | I9: =IS!I33 -> 34217.696 | J9: =IS!J33 -> 37707.9 | K9: =IS!K33 -> 40776.543 | L9: =IS!L33 -> 44453.714
A10: Deferred income taxes | C10: 1808 | D10: -8081 | E10: -7763 | F10: -5257 | G10: 8348 | H10: =-(BS!H14-BS!G14) -> 7665 | I10: =-(BS!I14-BS!H14) -> 0 | J10: =-(BS!J14-BS!I14) -> 0 | K10: =-(BS!K14-BS!J14) -> 0 | L10: =-(BS!L14-BS!K14) -> 0
A11: (Gain) loss on debt and equity securities, net | C11: -12270 | D11: 5519 | E11: 823 | F11: -2671 | G11: -24620 | H11: =-Assumptions!H$63 -> 0 | I11: =-Assumptions!I$63 -> 0 | J11: =-Assumptions!J$63 -> 0 | K11: =-Assumptions!K$63 -> 0 | L11: =-Assumptions!L$63 -> 0
A12: Other | C12: 1955 | D12: 3483 | E12: 4330 | F12: 3419 | G12: 2108 | H12: 0 | I12: 0 | J12: 0 | K12: 0 | L12: 0
A13: Changes in operating assets and liabilities:
A14: Accounts receivable, net | C14: -9095 | D14: -2317 | E14: -7833 | F14: -5891 | G14: -8779 | H14: =-(BS!H9-BS!G9) -> -13233.449 | I14: =-(BS!I9-BS!H9) -> -12940.306 | J14: =-(BS!J9-BS!I9) -> -12468.366 | K14: =-(BS!K9-BS!J9) -> -12183.375 | L14: =-(BS!L9-BS!K9) -> -12508.265
A15: Inventory | C15: 0 | D15: 0 | E15: 0 | F15: 0 | G15: 0 | H15: =-(BS!H10-BS!G10) -> -7087.9271 | I15: =-(BS!I10-BS!H10) -> -3793.6158 | J15: =-(BS!J10-BS!I10) -> -4104.2944 | K15: =-(BS!K10-BS!J10) -> -4056.9802 | L15: =-(BS!L10-BS!K10) -> -3150.3317
A16: Other assets | C16: -1846 | D16: -5046 | E16: -2143 | F16: -1397 | G16: -4542 | H16: =-(BS!H11-BS!G11)-(BS!H16-BS!G16)-(BS!H18-BS!G18) -> -15413.65 | I16: =-(BS!I11-BS!H11)-(BS!I16-BS!H16)-(BS!I18-BS!H18) -> -10109.331 | J16: =-(BS!J11-BS!I11)-(BS!J16-BS!I16)-(BS!J18-BS!I18) -> -9740.6373 | K16: =-(BS!K11-BS!J11)-(BS!K16-BS!J16)-(BS!K18-BS!J18) -> -9517.9942 | L16: =-(BS!L11-BS!K11)-(BS!L16-BS!K16)-(BS!L18-BS!K18) -> -9771.8074
A17: Accounts payable | C17: 283 | D17: 707 | E17: 664 | F17: 359 | G17: 907 | H17: =BS!H22-BS!G22 -> 3460.702 | I17: =BS!I22-BS!H22 -> 4245.4641 | J17: =BS!J22-BS!I22 -> 4786.565 | K17: =BS!K22-BS!J22 -> 4734.4161 | L17: =BS!L22-BS!K22 -> 4315.5228
A18: Accrued compensation and benefits | C18: 0 | D18: 0 | E18: 0 | F18: 0 | G18: 0 | H18: =BS!H23-BS!G23 -> 1951.2624 | I18: =BS!I23-BS!H23 -> 3314.5346 | J18: =BS!J23-BS!I23 -> 3193.6516 | K18: =BS!K23-BS!J23 -> 3120.6538 | L18: =BS!L23-BS!K23 -> 3203.8713
A19: Accrued expenses and other liabilities | C19: 7304 | D19: 3915 | E19: 3937 | F19: -1161 | G19: 12939 | H19: =(BS!H24-BS!G24)+(BS!H30-BS!G30)+(BS!H31-BS!G31) -> 15111.797 | I19: =(BS!I24-BS!H24)+(BS!I30-BS!H30)+(BS!I31-BS!H31) -> 14658.635 | J19: =(BS!J24-BS!I24)+(BS!J30-BS!I30)+(BS!J31-BS!I31) -> 14152.861 | K19: =(BS!K24-BS!J24)+(BS!K30-BS!J30)+(BS!K31-BS!J31) -> 13840.795 | L19: =(BS!L24-BS!K24)+(BS!L30-BS!K30)+(BS!L31-BS!K31) -> 14196.55
A20: Accrued revenue share | C20: 1682 | D20: -445 | E20: 482 | F20: 1059 | G20: 899 | H20: =BS!H25-BS!G25 -> 1809.2206 | I20: =BS!I25-BS!H25 -> 2154.4475 | J20: =BS!J25-BS!I25 -> 2075.8735 | K20: =BS!K25-BS!J25 -> 2028.425 | L20: =BS!L25-BS!K25 -> 2082.5163
A21: Deferred revenue | C21: 774 | D21: 367 | E21: 525 | F21: 1043 | G21: 2420 | H21: =BS!H26-BS!G26 -> 1708.3365 | I21: =BS!I26-BS!H26 -> 1408.6772 | J21: =BS!J26-BS!I26 -> 1357.3019 | K21: =BS!K26-BS!J26 -> 1326.2779 | L21: =BS!L26-BS!K26 -> 1361.6453
A22: Income taxes, net | C22: -625 | D22: 584 | E22: 523 | F22: -2418 | G22: -3226 | H22: =BS!H29-BS!G29 -> 1775 | I22: =BS!I29-BS!H29 -> 194 | J22: =BS!J29-BS!I29 -> 300 | K22: =BS!K29-BS!J29 -> 200 | L22: =BS!L29-BS!K29 -> 200
A23: Net cash provided by operating activities | C23: =SUM(C7:C12)+SUM(C14:C22) -> 91652 | D23: =SUM(D7:D12)+SUM(D14:D22) -> 91495 | E23: =SUM(E7:E12)+SUM(E14:E22) -> 101746 | F23: =SUM(F7:F12)+SUM(F14:F22) -> 125299 | G23: =SUM(G7:G12)+SUM(G14:G22) -> 164713 | H23: =SUM(H7:H12)+SUM(H14:H22) -> 196053.58 | I23: =SUM(I7:I12)+SUM(I14:I22) -> 235600.54 | J23: =SUM(J7:J12)+SUM(J14:J22) -> 274049.86 | ... L23: =SUM(L7:L12)+SUM(L14:L22) -> 350206.02
A25: Investing activities
A26: Purchases of property and equipment | C26: -24640 | D26: -31485 | E26: -32251 | F26: -52535 | G26: -91447 | H26: =-Schedules!H9 -> -200000 | I26: =-Schedules!I9 -> -260000 | J26: =-Schedules!J9 -> -290000 | K26: =-Schedules!K9 -> -300000 | L26: =-Schedules!L9 -> -305000
A27: Marketable securities, net of maturities and sales | C27: -6902 | D27: 18948 | E27: 8814 | F27: 16749 | G27: -20533 | H27: =-(BS!H8-BS!G8) -> -53865 | I27: =-(BS!I8-BS!H8) -> 20000 | J27: =-(BS!J8-BS!I8) -> 15000 | K27: =-(BS!K8-BS!J8) -> 10000 | L27: =-(BS!L8-BS!K8) -> 0
A28: Non-marketable securities, net of maturities and sales | C28: -1904 | D28: -2381 | E28: -2080 | F28: -4152 | G28: -4349 | H28: =-Assumptions!H$80 -> -22051 | I28: =-Assumptions!I$80 -> -5000 | J28: =-Assumptions!J$80 -> -5000 | K28: =-Assumptions!K$80 -> -5000 | L28: =-Assumptions!L$80 -> -5000
A29: Acquisitions, net of cash acquired, and intangibles | C29: -2618 | D29: -6969 | E29: -495 | F29: -2931 | G29: -1592 | H29: =-Assumptions!H$81 -> -33697 | I29: =-Assumptions!I$81 -> -2000 | J29: =-Assumptions!J$81 -> -2000 | K29: =-Assumptions!K$81 -> -2000 | L29: =-Assumptions!L$81 -> -2000
A30: Other investing activities | C30: 541 | D30: 1589 | E30: -1051 | F30: -2667 | G30: -2370 | H30: 0 | I30: 0 | J30: 0 | K30: 0 | L30: 0
A31: Net cash used in investing activities | C31: =SUM(C26:C30) -> -35523 | D31: =SUM(D26:D30) -> -20298 | E31: =SUM(E26:E30) -> -27063 | F31: =SUM(F26:F30) -> -45536 | G31: =SUM(G26:G30) -> -120291 | H31: =SUM(H26:H30) -> -309613 | I31: =SUM(I26:I30) -> -247000 | J31: =SUM(J26:J30) -> -282000 | ... L31: =SUM(L26:L30) -> -312000
A33: Financing activities
A34: Net payments related to stock-based award activities | C34: -10162 | D34: -9300 | E34: -9837 | F34: -12190 | G34: -14167 | H34: =-Schedules!H33 -> -24000 | I34: =-Schedules!I33 -> -20000 | J34: =-Schedules!J33 -> -21000 | K34: =-Schedules!K33 -> -22000 | L34: =-Schedules!L33 -> -23000
A35: Repurchases of stock | C35: -50274 | D35: -59296 | E35: -61504 | F35: -62222 | G35: -45709 | H35: =-Schedules!H31 -> 0 | I35: =-Schedules!I31 -> 0 | J35: =-Schedules!J31 -> -20000 | K35: =-Schedules!K31 -> -40000 | L35: =-Schedules!L31 -> -60000
A36: Common dividend payments | C36: 0 | D36: 0 | E36: 0 | F36: -7363 | G36: -10049 | H36: =-Schedules!H29 -> -10956.123 | I36: =-Schedules!I29 -> -12185.326 | J36: =-Schedules!J29 -> -13355.871 | K36: =-Schedules!K29 -> -14712.373 | L36: =-Schedules!L29 -> -16140.228
A37: Preferred dividend payments | C37: 0 | D37: 0 | E37: 0 | F37: 0 | G37: 0 | H37: =-Schedules!H30 -> -400 | I37: =-Schedules!I30 -> -1188 | J37: =-Schedules!J30 -> -1188 | K37: =-Schedules!K30 -> -1188 | L37: =-Schedules!L30 -> -1188
A38: Proceeds from issuance of debt, net of costs | C38: 20199 | D38: 52872 | E38: 10790 | F38: 13589 | G38: 64564 | H38: =Schedules!H18 -> 60000 | I38: =Schedules!I18 -> 45000 | J38: =Schedules!J18 -> 45000 | K38: =Schedules!K18 -> 40000 | L38: =Schedules!L18 -> 40000
A39: Repayments of debt | C39: -21435 | D39: -54068 | E39: -11550 | F39: -12701 | G39: -32427 | H39: =Schedules!H19 -> -5253 | I39: =Schedules!I19 -> -8000 | J39: =Schedules!J19 -> -10000 | K39: =Schedules!K19 -> -12000 | L39: =Schedules!L19 -> -15000
A40: Proceeds from equity issuance, net of costs | C40: 0 | D40: 0 | E40: 0 | F40: 0 | G40: 0 | H40: =Schedules!H34+Schedules!H35 -> 49562 | I40: =Schedules!I34+Schedules!I35 -> 10000 | J40: =Schedules!J34+Schedules!J35 -> 10000 | K40: =Schedules!K34+Schedules!K35 -> 10000 | L40: =Schedules!L34+Schedules!L35 -> 10000
A41: Other financing activities | C41: 310 | D41: 35 | E41: 8 | F41: 1154 | G41: 400 | H41: 0 | I41: 0 | J41: 0 | K41: 0 | L41: 0
A42: Net cash provided by (used in) financing activities | C42: =SUM(C34:C41) -> -61362 | D42: =SUM(D34:D41) -> -69757 | E42: =SUM(E34:E41) -> -72093 | F42: =SUM(F34:F41) -> -79733 | G42: =SUM(G34:G41) -> -37388 | H42: =SUM(H34:H41) -> 68952.877 | I42: =SUM(I34:I41) -> 13626.674 | J42: =SUM(J34:J41) -> -10543.871 | ... L42: =SUM(L34:L41) -> -65328.228
A44: Effect of exchange rate changes on cash | C44: -287 | D44: -506 | E44: -421 | F44: -612 | G44: 208 | H44: 0 | I44: 0 | J44: 0 | K44: 0 | L44: 0
...

Sheet Schedules
A1: ALPHABET INC. — SUPPORTING SCHEDULES
A2: PP&E / Depreciation · Debt & Interest · Shares & Dividends · Working Capital
A3: $ in millions unless noted. Fiscal year = calendar year. Historicals (FY2021A-FY2025A) are hardcoded from Alphabet 10-K filings; all FY2026E-FY2030E cells are formulas.
C5: FY2021A | D5: FY2022A | E5: FY2023A | F5: FY2024A | G5: FY2025A | H5: FY2026E | I5: FY2027E | J5: FY2028E | K5: FY2029E | L5: FY2030E
A6: PROPERTY & EQUIPMENT ROLL-FORWARD
A7: Beginning net property and equipment | C7: 84749 | D7: =C10 -> 97599 | E7: =D10 -> 112668 | F7: =E10 -> 134345 | G7: =F10 -> 171036 | H7: =G10 -> 246597 | I7: =H10 -> 414539.39 | J7: =I10 -> 612358.48 | K7: =J10 -> 801319.33 | L7: =K10 -> 961088.45
A8: Depreciation | C8: 10273 | D8: 13475 | E8: 11946 | F8: 15311 | G8: 21136 | H8: =H7*Assumptions!H$44 -> 32057.61 | I8: =I7*Assumptions!I$44 -> 62180.908 | J8: =J7*Assumptions!J$44 -> 101039.15 | K8: =K7*Assumptions!K$44 -> 140230.88 | L8: =L7*Assumptions!L$44 -> 172995.92
A9: Capital expenditure | C9: 24640 | D9: 31485 | E9: 32251 | F9: 52535 | G9: 91447 | H9: =Assumptions!H$50 -> 200000 | I9: =Assumptions!I$50 -> 260000 | J9: =Assumptions!J$50 -> 290000 | K9: =Assumptions!K$50 -> 300000 | L9: =Assumptions!L$50 -> 305000
A10: Ending net property and equipment | C10: 97599 | D10: 112668 | E10: 134345 | F10: 171036 | G10: 246597 | H10: =H7-H8+H9 -> 414539.39 | I10: =I7-I8+I9 -> 612358.48 | J10: =J7-J8+J9 -> 801319.33 | K10: =K7-K8+K9 -> 961088.45 | L10: =L7-L8+L9 -> 1093092.5
A11: Capex as % of revenue | C11: =C9/IS!C6 -> 0.095638437 | D11: =D9/IS!D6 -> 0.11131893 | E11: =E9/IS!E6 -> 0.10491747 | F11: =F9/IS!F6 -> 0.15009228 | G11: =G9/IS!G6 -> 0.22700801 | H11: =H9/IS!H6 -> 0.41031401 | I11: =I9/IS!I6 -> 0.45590446 | J11: =J9/IS!J6 -> 0.44606037 | ... L11: =L9/IS!L6 -> 0.3773588
A12: Depreciation as % of revenue | C12: =C8/IS!C6 -> 0.039873931 | D12: =D8/IS!D6 -> 0.04764245 | E12: =E8/IS!E6 -> 0.038862177 | F12: =F8/IS!F6 -> 0.043743465 | G12: =G8/IS!G6 -> 0.052468002 | H12: =H8/IS!H6 -> 0.065768433 | I12: =I8/IS!I6 -> 0.1090329 | J12: =J8/IS!J6 -> 0.15541228 | ... L12: =L8/IS!L6 -> 0.21403781
A13: Depreciation as % of beginning net PP&E | C13: =C8/C7 -> 0.12121677 | D13: =D8/D7 -> 0.13806494 | E13: =E8/E7 -> 0.10602833 | F13: =F8/F7 -> 0.11396777 | G13: =G8/G7 -> 0.12357632 | H13: =H8/H7 -> 0.13 | I13: =I8/I7 -> 0.15 | J13: =J8/J7 -> 0.165 | ... L13: =L8/L7 -> 0.18
A14: Implied average remaining life (years) | C14: =C10/C8 -> 9.5005354 | D14: =D10/D8 -> 8.3612616 | E14: =E10/E8 -> 11.246024 | F14: =F10/F8 -> 11.170792 | G14: =G10/G8 -> 11.667156 | H14: =H10/H8 -> 12.931076 | I14: =I10/I8 -> 9.8480144 | J14: =J10/J8 -> 7.9307807 | ... L14: =L10/L8 -> 6.3186029
A16: DEBT SCHEDULE & INTEREST
A17: Beginning long-term debt | C17: 13932 | D17: =C20 -> 14817 | E17: =D20 -> 14701 | F17: =E20 -> 13253 | G17: =F20 -> 10883 | H17: =G20 -> 46547 | I17: =H20 -> 101294 | J17: =I20 -> 138294 | K17: =J20 -> 173294 | L17: =K20 -> 201294
A18: Issuance | C18: 20199 | D18: 52872 | E18: 10790 | F18: 13589 | G18: 64564 | H18: =Assumptions!H$87 -> 60000 | I18: =Assumptions!I$87 -> 45000 | J18: =Assumptions!J$87 -> 45000 | K18: =Assumptions!K$87 -> 40000 | L18: =Assumptions!L$87 -> 40000
A19: Repayment | C19: -21435 | D19: -54068 | E19: -11550 | F19: -12701 | G19: -32427 | H19: =-Assumptions!H$88 -> -5253 | I19: =-Assumptions!I$88 -> -8000 | J19: =-Assumptions!J$88 -> -10000 | K19: =-Assumptions!K$88 -> -12000 | L19: =-Assumptions!L$88 -> -15000
A20: Ending long-term debt | C20: 14817 | D20: 14701 | E20: 13253 | F20: 10883 | G20: 46547 | H20: =H17+H18+H19 -> 101294 | I20: =I17+I18+I19 -> 138294 | J20: =J17+J18+J19 -> 173294 | K20: =K17+K18+K19 -> 201294 | L20: =L17+L18+L19 -> 226294
A21: Interest expense (on beginning debt) | H21: =IS!H18 -> -2001.521 | I21: =IS!I18 -> -4456.936 | J21: =IS!J18 -> -6084.936 | K21: =IS!K18 -> -7798.23 | L21: =IS!L18 -> -9058.23
A22: Beginning cash + marketable securities | D22: =BS!C7+BS!C8 -> 139649 | E22: =BS!D7+BS!D8 -> 113762 | F22: =BS!E7+BS!E8 -> 110916 | G22: =BS!F7+BS!F8 -> 95657 | H22: =BS!G7+BS!G8 -> 126843 | I22: =BS!H7+BS!H8 -> 136101.46 | J22: =BS!I7+BS!I8 -> 118328.67 | K22: =BS!J7+BS!J8 -> 84834.661 | L22: =BS!K7+BS!K8 -> 49242.719
A23: Interest and investment income (on beginning balance) | H23: =IS!H17 -> 5073.72 | I23: =IS!I17 -> 5171.8553 | J23: =IS!J17 -> 4259.8322 | K23: =IS!K17 -> 2969.2131 | L23: =IS!L17 -> 1723.4952
A24: Memo: net cash / (net debt) | C24: =BS!C7+BS!C8-C20 -> 124832 | D24: =BS!D7+BS!D8-D20 -> 99061 | E24: =BS!E7+BS!E8-E20 -> 97663 | F24: =BS!F7+BS!F8-F20 -> 84774 | G24: =BS!G7+BS!G8-G20 -> 80296 | H24: =BS!H7+BS!H8-H20 -> 34807.456 | I24: =BS!I7+BS!I8-I20 -> -19965.327 | J24: =BS!J7+BS!J8-J20 -> -88459.339 | ... L24: =BS!L7+BS!L8-L20 -> -204173.49
A26: SHARES, DIVIDENDS & STOCK-BASED COMPENSATION
A27: Diluted weighted-average shares (m) | C27: 13553 | D27: 13159 | E27: 12722 | F27: 12447 | G27: 12230 | H27: =IS!H28 -> 12450.14 | I27: =IS!I28 -> 12562.191 | J27: =IS!J28 -> 12599.878 | K27: =IS!K28 -> 12574.678 | L27: =IS!L28 -> 12511.805
A28: Common dividend per share ($) | C28: =C29/C27 -> 0 | D28: =D29/D27 -> 0 | E28: =E29/E27 -> 0 | F28: =F29/F27 -> 0.59154816 | G28: =G29/G27 -> 0.82166803 | H28: =Assumptions!H$93 -> 0.88 | I28: =Assumptions!I$93 -> 0.97 | J28: =Assumptions!J$93 -> 1.06 | K28: =Assumptions!K$93 -> 1.17 | L28: =Assumptions!L$93 -> 1.29
A29: Common dividends paid | C29: 0 | D29: 0 | E29: 0 | F29: 7363 | G29: 10049 | H29: =H27*H28 -> 10956.123 | I29: =I27*I28 -> 12185.326 | J29: =J27*J28 -> 13355.871 | K29: =K27*K28 -> 14712.373 | L29: =L27*L28 -> 16140.228
A30: Preferred dividends paid | C30: 0 | D30: 0 | E30: 0 | F30: 0 | G30: 0 | H30: =Assumptions!H$94 -> 400 | I30: =Assumptions!I$94 -> 1188 | J30: =Assumptions!J$94 -> 1188 | K30: =Assumptions!K$94 -> 1188 | L30: =Assumptions!L$94 -> 1188
A31: Share repurchases | C31: 50274 | D31: 59296 | E31: 61504 | F31: 62222 | G31: 45709 | H31: =Assumptions!H$92 -> 0 | I31: =Assumptions!I$92 -> 0 | J31: =Assumptions!J$92 -> 20000 | K31: =Assumptions!K$92 -> 40000 | L31: =Assumptions!L$92 -> 60000
A32: Stock-based compensation expense | C32: 15376 | D32: 19362 | E32: 22460 | F32: 22785 | G32: 24953 | H32: =IS!H33 -> 30220.757 | I32: =IS!I33 -> 34217.696 | J32: =IS!J33 -> 37707.9 | K32: =IS!K33 -> 40776.543 | L32: =IS!L33 -> 44453.714
A33: Net cash payments for SBC award activities | C33: 10162 | D33: 9300 | E33: 9837 | F33: 12190 | G33: 14167 | H33: =Assumptions!H$91 -> 24000 | I33: =Assumptions!I$91 -> 20000 | J33: =Assumptions!J$91 -> 21000 | K33: =Assumptions!K$91 -> 22000 | L33: =Assumptions!L$91 -> 23000
A34: Common equity issuance | C34: 0 | D34: 0 | E34: 0 | F34: 0 | G34: 0 | H34: =Assumptions!H$89 -> 31539 | I34: =Assumptions!I$89 -> 10000 | J34: =Assumptions!J$89 -> 10000 | K34: =Assumptions!K$89 -> 10000 | L34: =Assumptions!L$89 -> 10000
A35: Preferred equity issuance | C35: 0 | D35: 0 | E35: 0 | F35: 0 | G35: 0 | H35: =Assumptions!H$90 -> 18023 | I35: =Assumptions!I$90 -> 0 | J35: =Assumptions!J$90 -> 0 | K35: =Assumptions!K$90 -> 0 | L35: =Assumptions!L$90 -> 0
A37: WORKING CAPITAL METRICS (memo)
A38: Days sales outstanding | C38: =BS!C9/IS!C6*365 -> 55.682841 | D38: =BS!D9/IS!D6*365 -> 51.952969 | E38: =BS!E9/IS!E6*365 -> 56.95251 | F38: =BS!F9/IS!F6*365 -> 54.580336 | G38: =BS!G9/IS!G6*365 -> 56.97949 | H38: =BS!H9/IS!H6*365 -> 57 | I38: =BS!I9/IS!I6*365 -> 57 | J38: =BS!J9/IS!J6*365 -> 57 | ... L38: =BS!L9/IS!L6*365 -> 57
A39: Days payable outstanding | C39: =BS!C22/IS!C9*365 -> 19.862312 | D39: =BS!D22/IS!D9*365 -> 14.831026 | E39: =BS!E22/IS!E9*365 -> 20.512293 | F39: =BS!F22/IS!F9*365 -> 19.925738 | G39: =BS!G22/IS!G9*365 -> 27.397176 | H39: =BS!H22/IS!H9*365 -> 30 | I39: =BS!I22/IS!I9*365 -> 30 | J39: =BS!J22/IS!J9*365 -> 30 | ... L39: =BS!L22/IS!L9*365 -> 30
A40: Inventory as % of cost of revenues | C40: =BS!C10/IS!C9 -> 0.010546336 | D40: =BS!D10/IS!D9 -> 0 | E40: =BS!E10/IS!E9 -> 0 | F40: =BS!F10/IS!F9 -> 0 | G40: =BS!G10/IS!G9 -> 0.015005999 | H40: =BS!H10/IS!H9 -> 0.05 | I40: =BS!I10/IS!I9 -> 0.055 | J40: =BS!J10/IS!J9 -> 0.058 | ... L40: =BS!L10/IS!L9 -> 0.06
A41: Net working capital | C41: =BS!C12-BS!C7-BS!C8-BS!C27 -> -15760 | D41: =BS!D12-BS!D7-BS!D8-BS!D27 -> -18267 | E41: =BS!E12-BS!E7-BS!E8-BS!E27 -> -21200 | F41: =BS!F12-BS!F7-BS!F8-BS!F27 -> -21068 | G41: =BS!G12-BS!G7-BS!G8-BS!G27 -> -23550 | H41: =BS!H12-BS!H7-BS!H8-BS!H27 -> -19214.301 | I41: =BS!I12-BS!I7-BS!I8-BS!I27 -> -21889.839 | J41: =BS!J12-BS!J7-BS!J8-BS!J27 -> -24714.7 | ... L41: =BS!L12-BS!L7-BS!L8-BS!L27 -> -30800.39

Sheet Checks
A1: ALPHABET INC. — MODEL INTEGRITY CHECKS
A2: Audit dashboard — every check must read OK
A3: $ in millions unless noted. Fiscal year = calendar year. Historicals (FY2021A-FY2025A) are hardcoded from Alphabet 10-K filings; all FY2026E-FY2030E cells are formulas.
A5: MASTER STATUS | C5: =IF(COUNTIF(C10:L60,"ERROR")=0,"ALL CHECKS PASS","ERRORS DETECTED - REVIEW BELOW") -> ALL CHECKS PASS
C8: FY2021A | D8: FY2022A | E8: FY2023A | F8: FY2024A | G8: FY2025A | H8: FY2026E | I8: FY2027E | J8: FY2028E | K8: FY2029E | L8: FY2030E
A10: 1. Balance sheet balances (Assets - L&E) | C10: =IF(ABS(BS!C41)<0.5,"OK","ERROR") -> OK | D10: =IF(ABS(BS!D41)<0.5,"OK","ERROR") -> OK | E10: =IF(ABS(BS!E41)<0.5,"OK","ERROR") -> OK | F10: =IF(ABS(BS!F41)<0.5,"OK","ERROR") -> OK | G10: =IF(ABS(BS!G41)<0.5,"OK","ERROR") -> OK | H10: =IF(ABS(BS!H41)<0.5,"OK","ERROR") -> OK | I10: =IF(ABS(BS!I41)<0.5,"OK","ERROR") -> OK | J10: =IF(ABS(BS!J41)<0.5,"OK","ERROR") -> OK | ... L10: =IF(ABS(BS!L41)<0.5,"OK","ERROR") -> OK
A11: 2. Cash tie-out (CF ending cash - BS cash) | C11: =IF(ABS(CF!C47-BS!C7)<0.5,"OK","ERROR") -> OK | D11: =IF(ABS(CF!D47-BS!D7)<0.5,"OK","ERROR") -> OK | E11: =IF(ABS(CF!E47-BS!E7)<0.5,"OK","ERROR") -> OK | F11: =IF(ABS(CF!F47-BS!F7)<0.5,"OK","ERROR") -> OK | G11: =IF(ABS(CF!G47-BS!G7)<0.5,"OK","ERROR") -> OK | H11: =IF(ABS(CF!H47-BS!H7)<0.5,"OK","ERROR") -> OK | I11: =IF(ABS(CF!I47-BS!I7)<0.5,"OK","ERROR") -> OK | J11: =IF(ABS(CF!J47-BS!J7)<0.5,"OK","ERROR") -> OK | ... L11: =IF(ABS(CF!L47-BS!L7)<0.5,"OK","ERROR") -> OK
A12: 3. Net income link (IS net income - CF net income) | C12: =IF(ABS(IS!C24-CF!C7)<0.5,"OK","ERROR") -> OK | D12: =IF(ABS(IS!D24-CF!D7)<0.5,"OK","ERROR") -> OK | E12: =IF(ABS(IS!E24-CF!E7)<0.5,"OK","ERROR") -> OK | F12: =IF(ABS(IS!F24-CF!F7)<0.5,"OK","ERROR") -> OK | G12: =IF(ABS(IS!G24-CF!G7)<0.5,"OK","ERROR") -> OK | H12: =IF(ABS(IS!H24-CF!H7)<0.5,"OK","ERROR") -> OK | I12: =IF(ABS(IS!I24-CF!I7)<0.5,"OK","ERROR") -> OK | J12: =IF(ABS(IS!J24-CF!J7)<0.5,"OK","ERROR") -> OK | ... L12: =IF(ABS(IS!L24-CF!L7)<0.5,"OK","ERROR") -> OK
A13: 4. Total costs = sum of expense lines | C13: =IF(ABS(IS!C13-SUM(IS!C9:C12))<0.5,"OK","ERROR") -> OK | D13: =IF(ABS(IS!D13-SUM(IS!D9:D12))<0.5,"OK","ERROR") -> OK | E13: =IF(ABS(IS!E13-SUM(IS!E9:E12))<0.5,"OK","ERROR") -> OK | F13: =IF(ABS(IS!F13-SUM(IS!F9:F12))<0.5,"OK","ERROR") -> OK | G13: =IF(ABS(IS!G13-SUM(IS!G9:G12))<0.5,"OK","ERROR") -> OK | H13: =IF(ABS(IS!H13-SUM(IS!H9:H12))<0.5,"OK","ERROR") -> OK | I13: =IF(ABS(IS!I13-SUM(IS!I9:I12))<0.5,"OK","ERROR") -> OK | J13: =IF(ABS(IS!J13-SUM(IS!J9:J12))<0.5,"OK","ERROR") -> OK | ... L13: =IF(ABS(IS!L13-SUM(IS!L9:L12))<0.5,"OK","ERROR") -> OK
A14: 5. Total assets = current + non-current | C14: =IF(ABS(BS!C19-(BS!C12+SUM(BS!C13:C18)))<0.5,"OK","ERROR") -> OK | D14: =IF(ABS(BS!D19-(BS!D12+SUM(BS!D13:D18)))<0.5,"OK","ERROR") -> OK | E14: =IF(ABS(BS!E19-(BS!E12+SUM(BS!E13:E18)))<0.5,"OK","ERROR") -> OK | F14: =IF(ABS(BS!F19-(BS!F12+SUM(BS!F13:F18)))<0.5,"OK","ERROR") -> OK | G14: =IF(ABS(BS!G19-(BS!G12+SUM(BS!G13:G18)))<0.5,"OK","ERROR") -> OK | H14: =IF(ABS(BS!H19-(BS!H12+SUM(BS!H13:H18)))<0.5,"OK","ERROR") -> OK | I14: =IF(ABS(BS!I19-(BS!I12+SUM(BS!I13:I18)))<0.5,"OK","ERROR") -> OK | J14: =IF(ABS(BS!J19-(BS!J12+SUM(BS!J13:J18)))<0.5,"OK","ERROR") -> OK | ... L14: =IF(ABS(BS!L19-(BS!L12+SUM(BS!L13:L18)))<0.5,"OK","ERROR") -> OK
A15: 6. Total equity = sum of equity components | C15: =IF(ABS(BS!C38-SUM(BS!C34:C37))<0.5,"OK","ERROR") -> OK | D15: =IF(ABS(BS!D38-SUM(BS!D34:D37))<0.5,"OK","ERROR") -> OK | E15: =IF(ABS(BS!E38-SUM(BS!E34:E37))<0.5,"OK","ERROR") -> OK | F15: =IF(ABS(BS!F38-SUM(BS!F34:F37))<0.5,"OK","ERROR") -> OK | G15: =IF(ABS(BS!G38-SUM(BS!G34:G37))<0.5,"OK","ERROR") -> OK | H15: =IF(ABS(BS!H38-SUM(BS!H34:H37))<0.5,"OK","ERROR") -> OK | I15: =IF(ABS(BS!I38-SUM(BS!I34:I37))<0.5,"OK","ERROR") -> OK | J15: =IF(ABS(BS!J38-SUM(BS!J34:J37))<0.5,"OK","ERROR") -> OK | ... L15: =IF(ABS(BS!L38-SUM(BS!L34:L37))<0.5,"OK","ERROR") -> OK
A16: 7. PP&E roll-forward (projected years; see note 9) | H16: =IF(ABS(Schedules!H7-Schedules!H8+Schedules!H9-Schedules!H10)<0.5,"OK","ERROR") -> OK | I16: =IF(ABS(Schedules!I7-Schedules!I8+Schedules!I9-Schedules!I10)<0.5,"OK","ERROR") -> OK | J16: =IF(ABS(Schedules!J7-Schedules!J8+Schedules!J9-Schedules!J10)<0.5,"OK","ERROR") -> OK | K16: =IF(ABS(Schedules!K7-Schedules!K8+Schedules!K9-Schedules!K10)<0.5,"OK","ERROR") -> OK | L16: =IF(ABS(Schedules!L7-Schedules!L8+Schedules!L9-Schedules!L10)<0.5,"OK","ERROR") -> OK
A17: 8. Debt schedule ties to balance sheet | C17: =IF(ABS(Schedules!C20-BS!C28)<0.5,"OK","ERROR") -> OK | D17: =IF(ABS(Schedules!D20-BS!D28)<0.5,"OK","ERROR") -> OK | E17: =IF(ABS(Schedules!E20-BS!E28)<0.5,"OK","ERROR") -> OK | F17: =IF(ABS(Schedules!F20-BS!F28)<0.5,"OK","ERROR") -> OK | G17: =IF(ABS(Schedules!G20-BS!G28)<0.5,"OK","ERROR") -> OK | H17: =IF(ABS(Schedules!H20-BS!H28)<0.5,"OK","ERROR") -> OK | I17: =IF(ABS(Schedules!I20-BS!I28)<0.5,"OK","ERROR") -> OK | J17: =IF(ABS(Schedules!J20-BS!J28)<0.5,"OK","ERROR") -> OK | ... L17: =IF(ABS(Schedules!L20-BS!L28)<0.5,"OK","ERROR") -> OK
A18: 9. Depreciation ties to PP&E schedule | C18: =IF(ABS(IS!C31-Schedules!C8)<0.5,"OK","ERROR") -> OK | D18: =IF(ABS(IS!D31-Schedules!D8)<0.5,"OK","ERROR") -> OK | E18: =IF(ABS(IS!E31-Schedules!E8)<0.5,"OK","ERROR") -> OK | F18: =IF(ABS(IS!F31-Schedules!F8)<0.5,"OK","ERROR") -> OK | G18: =IF(ABS(IS!G31-Schedules!G8)<0.5,"OK","ERROR") -> OK | H18: =IF(ABS(IS!H31-Schedules!H8)<0.5,"OK","ERROR") -> OK | I18: =IF(ABS(IS!I31-Schedules!I8)<0.5,"OK","ERROR") -> OK | J18: =IF(ABS(IS!J31-Schedules!J8)<0.5,"OK","ERROR") -> OK | ... L18: =IF(ABS(IS!L31-Schedules!L8)<0.5,"OK","ERROR") -> OK
A19: 10. SBC in cash flow ties to income statement | C19: =IF(ABS(CF!C9-IS!C33)<0.5,"OK","ERROR") -> OK | D19: =IF(ABS(CF!D9-IS!D33)<0.5,"OK","ERROR") -> OK | E19: =IF(ABS(CF!E9-IS!E33)<0.5,"OK","ERROR") -> OK | F19: =IF(ABS(CF!F9-IS!F33)<0.5,"OK","ERROR") -> OK | G19: =IF(ABS(CF!G9-IS!G33)<0.5,"OK","ERROR") -> OK | H19: =IF(ABS(CF!H9-IS!H33)<0.5,"OK","ERROR") -> OK | I19: =IF(ABS(CF!I9-IS!I33)<0.5,"OK","ERROR") -> OK | J19: =IF(ABS(CF!J9-IS!J33)<0.5,"OK","ERROR") -> OK | ... L19: =IF(ABS(CF!L9-IS!L33)<0.5,"OK","ERROR") -> OK
A20: 11. Capex in cash flow ties to PP&E schedule | C20: =IF(ABS(CF!C26+Schedules!C9)<0.5,"OK","ERROR") -> OK | D20: =IF(ABS(CF!D26+Schedules!D9)<0.5,"OK","ERROR") -> OK | E20: =IF(ABS(CF!E26+Schedules!E9)<0.5,"OK","ERROR") -> OK | F20: =IF(ABS(CF!F26+Schedules!F9)<0.5,"OK","ERROR") -> OK | G20: =IF(ABS(CF!G26+Schedules!G9)<0.5,"OK","ERROR") -> OK | H20: =IF(ABS(CF!H26+Schedules!H9)<0.5,"OK","ERROR") -> OK | I20: =IF(ABS(CF!I26+Schedules!I9)<0.5,"OK","ERROR") -> OK | J20: =IF(ABS(CF!J26+Schedules!J9)<0.5,"OK","ERROR") -> OK | ... L20: =IF(ABS(CF!L26+Schedules!L9)<0.5,"OK","ERROR") -> OK
A21: 12. Cash opening balance = prior period close | D21: =IF(ABS(CF!D46-CF!C47)<0.5,"OK","ERROR") -> OK | E21: =IF(ABS(CF!E46-CF!D47)<0.5,"OK","ERROR") -> OK | F21: =IF(ABS(CF!F46-CF!E47)<0.5,"OK","ERROR") -> OK | G21: =IF(ABS(CF!G46-CF!F47)<0.5,"OK","ERROR") -> OK | H21: =IF(ABS(CF!H46-CF!G47)<0.5,"OK","ERROR") -> OK | I21: =IF(ABS(CF!I46-CF!H47)<0.5,"OK","ERROR") -> OK | J21: =IF(ABS(CF!J46-CF!I47)<0.5,"OK","ERROR") -> OK | K21: =IF(ABS(CF!K46-CF!J47)<0.5,"OK","ERROR") -> OK | L21: =IF(ABS(CF!L46-CF!K47)<0.5,"OK","ERROR") -> OK
A22: 13. Retained earnings roll-forward (proj. only) | H22: =IF(ABS(BS!H37-(BS!G37+IS!H24-Schedules!H29-Schedules!H30-Schedules!H31))<0.5,"OK","ERROR") -> OK | I22: =IF(ABS(BS!I37-(BS!H37+IS!I24-Schedules!I29-Schedules!I30-Schedules!I31))<0.5,"OK","ERROR") -> OK | J22: =IF(ABS(BS!J37-(BS!I37+IS!J24-Schedules!J29-Schedules!J30-Schedules!J31))<0.5,"OK","ERROR") -> OK | K22: =IF(ABS(BS!K37-(BS!J37+IS!K24-Schedules!K29-Schedules!K30-Schedules!K31))<0.5,"OK","ERROR") -> OK | L22: =IF(ABS(BS!L37-(BS!K37+IS!L24-Schedules!L29-Schedules!L30-Schedules!L31))<0.5,"OK","ERROR") -> OK
A23: 14. APIC roll-forward (proj. only) | H23: =IF(ABS(BS!H35-(BS!G35+Schedules!H32-Schedules!H33+Schedules!H34))<0.5,"OK","ERROR") -> OK | I23: =IF(ABS(BS!I35-(BS!H35+Schedules!I32-Schedules!I33+Schedules!I34))<0.5,"OK","ERROR") -> OK | J23: =IF(ABS(BS!J35-(BS!I35+Schedules!J32-Schedules!J33+Schedules!J34))<0.5,"OK","ERROR") -> OK | K23: =IF(ABS(BS!K35-(BS!J35+Schedules!K32-Schedules!K33+Schedules!K34))<0.5,"OK","ERROR") -> OK | L23: =IF(ABS(BS!L35-(BS!K35+Schedules!L32-Schedules!L33+Schedules!L34))<0.5,"OK","ERROR") -> OK
A24: 15. Preferred stock roll-forward (proj. only) | H24: =IF(ABS(BS!H34-(BS!G34+Schedules!H35))<0.5,"OK","ERROR") -> OK | I24: =IF(ABS(BS!I34-(BS!H34+Schedules!I35))<0.5,"OK","ERROR") -> OK | J24: =IF(ABS(BS!J34-(BS!I34+Schedules!J35))<0.5,"OK","ERROR") -> OK | K24: =IF(ABS(BS!K34-(BS!J34+Schedules!K35))<0.5,"OK","ERROR") -> OK | L24: =IF(ABS(BS!L34-(BS!K34+Schedules!L35))<0.5,"OK","ERROR") -> OK
A26: FORMULA INTEGRITY (whole model)
A27: 16. No error values on Income Statement | C27: =IF(SUMPRODUCT(--ISERROR(IS!C6:L33))=0,"OK","ERROR") -> OK
A28: 17. No error values on Balance Sheet | C28: =IF(SUMPRODUCT(--ISERROR(BS!C7:L41))=0,"OK","ERROR") -> OK
A29: 18. No error values on Cash Flow | C29: =IF(SUMPRODUCT(--ISERROR(CF!C7:L50))=0,"OK","ERROR") -> OK
A30: 19. No error values on Schedules | C30: =IF(SUMPRODUCT(--ISERROR(Schedules!C7:L41))=0,"OK","ERROR") -> OK
A31: 20. No error values on Assumptions | C31: =IF(SUMPRODUCT(--ISERROR(Assumptions!H11:L95))=0,"OK","ERROR") -> OK
A33: SCENARIO HIERARCHY (driver-level, holds regardless of toggle position)
A34: 21. Revenue growth: Upside > Base > Downside | H34: =IF(AND(Assumptions!H12>Assumptions!H11,Assumptions!H11>Assumptions!H13),"OK","ERROR") -> OK | I34: =IF(AND(Assumptions!I12>Assumptions!I11,Assumptions!I11>Assumptions!I13),"OK","ERROR") -> OK | J34: =IF(AND(Assumptions!J12>Assumptions!J11,Assumptions!J11>Assumptions!J13),"OK","ERROR") -> OK | K34: =IF(AND(Assumptions!K12>Assumptions!K11,Assumptions!K11>Assumptions!K13),"OK","ERROR") -> OK | L34: =IF(AND(Assumptions!L12>Assumptions!L11,Assumptions!L11>Assumptions!L13),"OK","ERROR") -> OK
A35: 22. Cost of revenues %: Upside < Base < Downside | H35: =IF(AND(Assumptions!H18<Assumptions!H17,Assumptions!H17<Assumptions!H19),"OK","ERROR") -> OK | I35: =IF(AND(Assumptions!I18<Assumptions!I17,Assumptions!I17<Assumptions!I19),"OK","ERROR") -> OK | J35: =IF(AND(Assumptions!J18<Assumptions!J17,Assumptions!J17<Assumptions!J19),"OK","ERROR") -> OK | K35: =IF(AND(Assumptions!K18<Assumptions!K17,Assumptions!K17<Assumptions!K19),"OK","ERROR") -> OK | L35: =IF(AND(Assumptions!L18<Assumptions!L17,Assumptions!L17<Assumptions!L19),"OK","ERROR") -> OK
A36: 23. R&D %: Upside < Base < Downside | H36: =IF(AND(Assumptions!H24<Assumptions!H23,Assumptions!H23<Assumptions!H25),"OK","ERROR") -> OK | I36: =IF(AND(Assumptions!I24<Assumptions!I23,Assumptions!I23<Assumptions!I25),"OK","ERROR") -> OK | J36: =IF(AND(Assumptions!J24<Assumptions!J23,Assumptions!J23<Assumptions!J25),"OK","ERROR") -> OK | K36: =IF(AND(Assumptions!K24<Assumptions!K23,Assumptions!K23<Assumptions!K25),"OK","ERROR") -> OK | L36: =IF(AND(Assumptions!L24<Assumptions!L23,Assumptions!L23<Assumptions!L25),"OK","ERROR") -> OK
A37: 24. Sales & marketing %: Upside < Base < Downside | H37: =IF(AND(Assumptions!H30<Assumptions!H29,Assumptions!H29<Assumptions!H31),"OK","ERROR") -> OK | I37: =IF(AND(Assumptions!I30<Assumptions!I29,Assumptions!I29<Assumptions!I31),"OK","ERROR") -> OK | J37: =IF(AND(Assumptions!J30<Assumptions!J29,Assumptions!J29<Assumptions!J31),"OK","ERROR") -> OK | K37: =IF(AND(Assumptions!K30<Assumptions!K29,Assumptions!K29<Assumptions!K31),"OK","ERROR") -> OK | L37: =IF(AND(Assumptions!L30<Assumptions!L29,Assumptions!L29<Assumptions!L31),"OK","ERROR") -> OK
A38: 25. G&A %: Upside < Base < Downside | H38: =IF(AND(Assumptions!H36<Assumptions!H35,Assumptions!H35<Assumptions!H37),"OK","ERROR") -> OK | I38: =IF(AND(Assumptions!I36<Assumptions!I35,Assumptions!I35<Assumptions!I37),"OK","ERROR") -> OK | J38: =IF(AND(Assumptions!J36<Assumptions!J35,Assumptions!J35<Assumptions!J37),"OK","ERROR") -> OK | K38: =IF(AND(Assumptions!K36<Assumptions!K35,Assumptions!K35<Assumptions!K37),"OK","ERROR") -> OK | L38: =IF(AND(Assumptions!L36<Assumptions!L35,Assumptions!L35<Assumptions!L37),"OK","ERROR") -> OK
A39: 26. Depreciation rate: Upside < Base < Downside | H39: =IF(AND(Assumptions!H42<Assumptions!H41,Assumptions!H41<Assumptions!H43),"OK","ERROR") -> OK | I39: =IF(AND(Assumptions!I42<Assumptions!I41,Assumptions!I41<Assumptions!I43),"OK","ERROR") -> OK | J39: =IF(AND(Assumptions!J42<Assumptions!J41,Assumptions!J41<Assumptions!J43),"OK","ERROR") -> OK | K39: =IF(AND(Assumptions!K42<Assumptions!K41,Assumptions!K41<Assumptions!K43),"OK","ERROR") -> OK | L39: =IF(AND(Assumptions!L42<Assumptions!L41,Assumptions!L41<Assumptions!L43),"OK","ERROR") -> OK
A40: 27. Effective tax rate: Upside < Base < Downside | H40: =IF(AND(Assumptions!H54<Assumptions!H53,Assumptions!H53<Assumptions!H55),"OK","ERROR") -> OK | I40: =IF(AND(Assumptions!I54<Assumptions!I53,Assumptions!I53<Assumptions!I55),"OK","ERROR") -> OK | J40: =IF(AND(Assumptions!J54<Assumptions!J53,Assumptions!J53<Assumptions!J55),"OK","ERROR") -> OK | K40: =IF(AND(Assumptions!K54<Assumptions!K53,Assumptions!K53<Assumptions!K55),"OK","ERROR") -> OK | L40: =IF(AND(Assumptions!L54<Assumptions!L53,Assumptions!L53<Assumptions!L55),"OK","ERROR") -> OK
A42: KEY OUTPUTS (active scenario)
A43: Revenue | C43: =IS!C6 -> 257637 | D43: =IS!D6 -> 282836 | E43: =IS!E6 -> 307394 | F43: =IS!F6 -> 350018 | G43: =IS!G6 -> 402836 | H43: =IS!H6 -> 487431.56 | I43: =IS!I6 -> 570294.93 | J43: =IS!J6 -> 650136.21 | ... L43: =IS!L6 -> 808249.34
A44: Revenue growth % | C44: =IS!C7 -> 0 | D44: =IS!D7 -> 0.097808156 | E44: =IS!E7 -> 0.086827702 | F44: =IS!F7 -> 0.13866243 | G44: =IS!G7 -> 0.15090081 | H44: =IS!H7 -> 0.21 | I44: =IS!I7 -> 0.17 | J44: =IS!J7 -> 0.14 | ... L44: =IS!L7 -> 0.11
A45: Income from operations | C45: =IS!C14 -> 78714 | D45: =IS!D14 -> 74842 | E45: =IS!E14 -> 84293 | F45: =IS!F14 -> 112390 | G45: =IS!G14 -> 129039 | H45: =IS!H14 -> 164864.74 | I45: =IS!I14 -> 172210.31 | J45: =IS!J14 -> 169417.52 | ... L45: =IS!L14 -> 171318.3
A46: Operating margin % | C46: =IS!C15 -> 0.30552289 | D46: =IS!D15 -> 0.26461271 | E46: =IS!E15 -> 0.2742181 | F46: =IS!F15 -> 0.32109777 | G46: =IS!G15 -> 0.32032639 | H46: =IS!H15 -> 0.33823157 | I46: =IS!I15 -> 0.3019671 | J46: =IS!J15 -> 0.26058772 | ... L46: =IS!L15 -> 0.21196219
A47: EBITDA | C47: =IS!C32 -> 88987 | D47: =IS!D32 -> 88317 | E47: =IS!E32 -> 96239 | F47: =IS!F32 -> 127701 | G47: =IS!G32 -> 150175 | H47: =IS!H32 -> 196922.35 | I47: =IS!I32 -> 234391.21 | J47: =IS!J32 -> 270456.67 | ... L47: =IS!L32 -> 344314.22
...
