Workbook

Sheet DCF
A1: ALPHABET INC. (NASDAQ: GOOGL / GOOG) — DISCOUNTED CASH FLOW MODEL
A2: Ticker: GOOG | FYE: 31 December | Valuation date: 1-Jan-2026 (FY2025 year-end balance sheet) | $ in millions except per-share
A3: FY2026E–FY2030E assumptions mirror GOOG_3_Statement_Model.xlsx (Base/Upside/Downside). FY2031E–FY2035E are a capex-normalisation extension built for this DCF.
A4: Blue font = hardcoded input | Black font = formula | Green font = link to WACC sheet
A6: CASE SELECTOR
A7: Selected case (1 = Bear · 2 = Base · 3 = Bull) | B7: 2 | C7: =IF($B$7=1,"BEAR",IF($B$7=2,"BASE","BULL")) -> BASE
A9: MARKET DATA & VALUATION INPUTS
A10: Current share price ($) | B10: 335.31
A11: Diluted shares outstanding (m) | B11: 12450
A12: Market capitalisation ($m) | B12: =B10*B11 -> 4174609.5
A13: Cash, equivalents & marketable securities ($m) | B13: 126843
A14: Total debt ($m) | B14: 46547
A15: Net cash / (net debt) ($m) | B15: =B13-B14 -> 80296
A16: WACC — selected (from WACC sheet) | B16: =WACC!B36 -> 0.0925
A17: Terminal capex as multiple of terminal D&A (x) | B17: 1.15
A18: Change in NWC as % of change in revenue | B18: -0.018
A19: Valuation roll-forward to 8-Sep-2026 (years) | B19: 0.685
A20: BEAR CASE ASSUMPTIONS (= 3-statement model Downside, extended)
A21: Assumption | G21: FY2026E | H21: FY2027E | I21: FY2028E | J21: FY2029E | K21: FY2030E | L21: FY2031E | M21: FY2032E | N21: FY2033E | O21: FY2034E | P21: FY2035E
A22: Revenue growth (%) | G22: 0.185 | H22: 0.12 | I22: 0.09 | J22: 0.07 | K22: 0.06 | L22: 0.05 | M22: 0.045 | N22: 0.04 | O22: 0.035 | P22: 0.03
A23: Cost of revenues ex-D&A (% of revenue) | G23: 0.345 | H23: 0.355 | I23: 0.365 | J23: 0.372 | K23: 0.378 | L23: 0.38 | M23: 0.381 | N23: 0.382 | O23: 0.382 | P23: 0.383
A24: Research & development ex-D&A (% of revenue) | G24: 0.15 | H24: 0.156 | I24: 0.161 | J24: 0.165 | K24: 0.168 | L24: 0.169 | M24: 0.17 | N24: 0.17 | O24: 0.171 | P24: 0.171
A25: Sales & marketing (% of revenue) | G25: 0.071 | H25: 0.073 | I25: 0.075 | J25: 0.076 | K25: 0.077 | L25: 0.077 | M25: 0.078 | N25: 0.078 | O25: 0.078 | P25: 0.078
A26: General & administrative (% of revenue) | G26: 0.049 | H26: 0.05 | I26: 0.051 | J26: 0.052 | K26: 0.053 | L26: 0.053 | M26: 0.053 | N26: 0.054 | O26: 0.054 | P26: 0.054
A27: Depreciation (% of beginning net PP&E) | G27: 0.133 | H27: 0.158 | I27: 0.178 | J27: 0.192 | K27: 0.2 | L27: 0.2 | M27: 0.195 | N27: 0.19 | O27: 0.185 | P27: 0.18
A28: Capital expenditure ($m) | G28: 200000 | H28: 250000 | I28: 230000 | J28: 200000 | K28: 180000 | L28: 175000 | M28: 175000 | N28: 180000 | O28: 185000 | P28: 190000
A29: Effective tax rate (%) | G29: 0.195 | H29: 0.2 | I29: 0.205 | J29: 0.205 | K29: 0.205 | L29: 0.205 | M29: 0.205 | N29: 0.205 | O29: 0.205 | P29: 0.205
A30: Terminal growth rate (%) | G30: 0.02
A31: WACC spread vs. selected WACC (%) | G31: 0.01
A33: BASE CASE ASSUMPTIONS (= 3-statement model Base, extended)
A34: Assumption | G34: FY2026E | H34: FY2027E | I34: FY2028E | J34: FY2029E | K34: FY2030E | L34: FY2031E | M34: FY2032E | N34: FY2033E | O34: FY2034E | P34: FY2035E
A35: Revenue growth (%) | G35: 0.21 | H35: 0.17 | I35: 0.14 | J35: 0.12 | K35: 0.11 | L35: 0.095 | M35: 0.08 | N35: 0.07 | O35: 0.06 | P35: 0.05
A36: Cost of revenues ex-D&A (% of revenue) | G36: 0.335 | H36: 0.332 | I36: 0.33 | J36: 0.328 | K36: 0.326 | L36: 0.324 | M36: 0.322 | N36: 0.32 | O36: 0.319 | P36: 0.318
A37: Research & development ex-D&A (% of revenue) | G37: 0.145 | H37: 0.144 | I37: 0.143 | J37: 0.142 | K37: 0.141 | L37: 0.14 | M37: 0.139 | N37: 0.138 | O37: 0.138 | P37: 0.137
A38: Sales & marketing (% of revenue) | G38: 0.069 | H38: 0.068 | I38: 0.067 | J38: 0.066 | K38: 0.065 | L38: 0.064 | M38: 0.063 | N38: 0.063 | O38: 0.062 | P38: 0.062
A39: General & administrative (% of revenue) | G39: 0.047 | H39: 0.045 | I39: 0.044 | J39: 0.043 | K39: 0.042 | L39: 0.041 | M39: 0.04 | N39: 0.04 | O39: 0.039 | P39: 0.039
A40: Depreciation (% of beginning net PP&E) | G40: 0.13 | H40: 0.15 | I40: 0.165 | J40: 0.175 | K40: 0.18 | L40: 0.18 | M40: 0.175 | N40: 0.17 | O40: 0.165 | P40: 0.16
A41: Capital expenditure ($m) | G41: 200000 | H41: 260000 | I41: 290000 | J41: 300000 | K41: 305000 | L41: 295000 | M41: 285000 | N41: 280000 | O41: 275000 | P41: 275000
A42: Effective tax rate (%) | G42: 0.19 | H42: 0.19 | I42: 0.19 | J42: 0.19 | K42: 0.19 | L42: 0.19 | M42: 0.19 | N42: 0.19 | O42: 0.19 | P42: 0.19
A43: Terminal growth rate (%) | G43: 0.03
...

Sheet WACC
A1: ALPHABET INC. — WEIGHTED AVERAGE COST OF CAPITAL
A2: Market data as of 4-Sep-2026 close | $ in millions | Blue = input, black = formula, green = link to DCF sheet
A4: COST OF EQUITY (CAPM)
A5: Risk-free rate (10Y US Treasury) | B5: 0.0477
A6: Levered beta (5-year monthly) | B6: 1.24
A7: Equity risk premium | B7: 0.055
A8: Cost of equity (CAPM) | B8: =B5+B6*B7 -> 0.1159
A10: COST OF DEBT
A11: Credit rating (Moody's / S&P) | B11: Aa2 / AA+
A12: Pre-tax cost of debt | B12: 0.0525
A13: Effective tax rate (live, from DCF) | B13: =DCF!G68 -> 0.19
A14: After-tax cost of debt | B14: =B12*(1-B13) -> 0.042525
A16: CAPITAL STRUCTURE (market values)
A17: Current share price ($) | B17: =DCF!B10 -> 335.31
A18: Diluted shares outstanding (m) | B18: =DCF!B11 -> 12450
A19: Market capitalisation ($m) | B19: =B17*B18 -> 4174609.5
A20: Total debt ($m) | B20: =DCF!B14 -> 46547
A21: Cash, equivalents & marketable securities ($m) | B21: =DCF!B13 -> 126843
A22: Net cash / (net debt) ($m) | B22: =B21-B20 -> 80296
A23: Total capitalisation — market equity + gross debt ($m) | B23: =B19+B20 -> 4221156.5
A24: Note: WACC weights use GROSS debt (Alphabet is in a net cash position; net-debt weights would produce a negative debt weight and a WACC above the cost of equity). Net cash is credited in the DCF equity bridge instead.
A26: WACC CALCULATION
A27: Component | B27: Weight | C27: Cost | D27: Contribution
A28: Equity | B28: =B19/B23 -> 0.98897293 | C28: =B8 -> 0.1159 | D28: =B28*C28 -> 0.11462196
A29: Debt | B29: =B20/B23 -> 0.011027073 | C29: =B14 -> 0.042525 | D29: =B29*C29 -> 0.00046892627
A30: Total | B30: =B28+B29 -> 1 | D30: =D28+D29 -> 0.11509089
A31: WACC — CAPM output | B31: =D30 -> 0.11509089
A33: WACC SELECTION
A34: WACC method (1 = CAPM · 2 = Override) | B34: 2
A35: Override WACC (%) | B35: 0.0925
A36: WACC — SELECTED (used in DCF) | B36: =IF(B34=1,B31,B35) -> 0.0925
